Workbook
Name ____WO1: #REF!
Name ___WO1: #REF!
Name __A23: #N/A
Name __A23: [0]!__A23
Name __ASI87: #N/A
Name __ASI87: [0]!__ASI87
Name __d1: #N/A
Name __d1: [0]!__d1
Name __d6: #N/A
Name __d6: [0]!__d6
Name __D7: #N/A
Name __D7: [0]!__D7
Name __d8: #N/A
Name __d8: [0]!__d8
Name __DAS4556: #N/A
Name __DAS4556: [0]!__DAS4556
Name __ddf1: #N/A
Name __ddf1: [0]!__ddf1
Name __DDS12: #N/A
Name __DDS12: [0]!__DDS12
Name __ds1: #N/A
Name __ds1: [0]!__ds1
Name __DSS1: #N/A
Name __DSS1: [0]!__DSS1
Name __f31: #N/A
Name __f31: [0]!__f31
Name __F4: #N/A
Name __F4: [0]!__F4
Name __F5: #N/A
Name __F5: [0]!__F5
Name __fa213: #N/A
Name __fa213: [0]!__fa213
Name __far45: #N/A
Name __far45: [0]!__far45
Name __fd543: #N/A
Name __fd543: [0]!__fd543
Name __fdd32: #N/A
Name __fdd32: [0]!__fdd32
Name __FDD456: #N/A
Name __FDD456: [0]!__FDD456
Name __FGD4321: #N/A
Name __FGD4321: [0]!__FGD4321
Name __FSD4: #N/A
Name __FSD4: [0]!__FSD4
Name __fsf6: #N/A
Name __fsf6: [0]!__fsf6
Name __G4: #N/A
Name __G4: [0]!__G4
Name __G5: #N/A
Name __G5: [0]!__G5
Name __g7: #N/A
Name __g7: [0]!__g7
Name __g987: #N/A
Name __g987: [0]!__g987
Name __GF54: #N/A
Name __GF54: [0]!__GF54
Name __GFF54: #N/A
Name __GFF54: [0]!__GFF54
Name __ghg655: #N/A
Name __ghg655: [0]!__ghg655

Sheet LP
B2: LISTA DE PRECIOS DYNADRILL ECUADOR C.A.
B4: CODIGO | C4: DESCRIPCION DE ITEMS | D4: UNIDAD | E4: Nuevo Precio | F4: Tipo
B5: 2.2.15 Servicios de Estimulación y Limpieza de Pozos
A6: 1 | B6: SB3201 | C6: Viaje por unidad de bombeo para estimulación | D6: km | E6: 3.15 | F6: Servicio
A7: =A6+1 -> 2 | B7: SB3205 | C7: Unidad de bombeo para estimulación por hora adicional o fracción | D7: hr | E7: 26.78 | F7: Servicio
A8: =A7+1 -> 3 | B8: SB3206 | C8: Mezcla de materiales suministrados por la contratista. | D8: gls | E8: 0.09 | F8: Servicio
A9: =A8+1 -> 4 | B9: SB3207 | C9: Mezcla de materiales no suministrados por la contratista. | D9: gls | E9: 0.25 | F9: Servicio
A10: =A9+1 -> 5 | B10: SB3208 | C10: Bombeo de ácido primeros 2.000 galones | D10: gls | E10: 0.33 | F10: Servicio
A11: =A10+1 -> 6 | B11: SB3209 | C11: Bombeo de ácido de 2.001 a 4.000 galones | D11: gls | E11: 0.33 | F11: Servicio
A12: =A11+1 -> 7 | B12: SB3210 | C12: Bombeo de ácido de 4001 galones en adelante | D12: gls | E12: 0.33 | F12: Servicio
A13: =A12+1 -> 8 | B13: SB3211 | C13: Bombeo de fluidos no corrosivos primeros 2.000 galones | D13: gls | E13: 0.25 | F13: Servicio
A14: =A13+1 -> 9 | B14: SB3212 | C14: Bombeo de fluidos no corrosivos de 2.001 a 4.000 galones | D14: gls | E14: 0.25 | F14: Servicio
A15: =A14+1 -> 10 | B15: SB3213 | C15: Bombeo de Fluidos no corrosivos de 4001 galones en adelante | D15: gls | E15: 0.25 | F15: Servicio
A16: =A15+1 -> 11 | B16: SB3214 | C16: Tanque para tratamiento de 100 barriles | D16: unidad | E16: 257.1 | F16: Servicio
A17: =A16+1 -> 12 | B17: SB3215 | C17: Tanques para ácido o solventes de 1.000 a 1500 galones | D17: unidad | E17: 398.49 | F17: Servicio
A18: =A17+1 -> 13 | B18: SB3216 | C18: Cargo por monitoreo standard de presión, caudal y densidad | D18: unidad | E18: 373.8 | F18: Servicio
... A178: =A177+1 -> 173 | B178: Q21151 | C178: Arena Sand Jet Perforación Micro arena | D178: lbs | E178: 1.32 | F178: Material
B179: 2.2.14 Servicios de Completacion de Pozos
A180: =A178+1 -> 174 | B180: PCK 50001 | C180: HYDRAULIC SET RETRIEVABLE PACKER 5" x 2 3/8'' EUE Box-Pin CASING 5'' WEIGHT 18-21 lbs/FT | D180: unidad | E180: 9544.5 | F180: Material
A181: =A180+1 -> 175 | B181: PCK 50002 | C181: HYDRAULIC SET RETRIEVABLE PACKER 7" x 2 7/8'' EUE Box-Pin CASING 7'' WEIGHT 26-29 lbs/FT | D181: unidad | E181: 10092.95 | F181: Material
A182: =A181+1 -> 176 | B182: PCK 50003 | C182: HYDRAULIC SET RETRIEVABLE PACKER 7" x 3 1/2'' EUE Box-Pin CASING 7'' WEIGHT 26-29 lbs/FT | D182: unidad | E182: 11570.33 | F182: Material
A183: =A182+1 -> 177 | B183: PCK 50004 | C183: HYDRAULIC SET RETRIEVABLE PACKER 9 5/8" x 3 1/2'' EUE Box-Pin CASING 9 5/8'' WEIGHT 43.5-53.5 lbs/FT | D183: unidad | E183: 20084.99 | F183: Material
A184: =A183+1 -> 178 | B184: PCK 50005 | C184: RETRIEVABLE HYDRAULIC PACKER STRING 7" x 2 7/8'' EUE Box-Pin CASING 7'' WEIGHT 26-29 lbs/FT | D184: unidad | E184: 9729.69 | F184: Material
A185: =A184+1 -> 179 | B185: PCK 50006 | C185: RETRIEVABLE HYDRAULIC PACKER STRING 7" x 3 1/2'' EUE Box-Pin CASING 7'' WEIGHT 26-29 lbs/FT | D185: unidad | E185: 11570.33 | F185: Material
A186: =A185+1 -> 180 | B186: PCK 50007 | C186: RETRIEVABLE HYDRAULIC PACKER STRING 9 5/8" x 3 1/2'' EUE Box-Pin CASING 9 5/8'' WEIGHT 47-53.5 lbs/FT | D186: unidad | E186: 19358.45 | F186: Material
A187: =A186+1 -> 181 | B187: PCK 50008 | C187: DOUBLE GRIP RETRIEVABLE PACKER MODEL R 5" x 2 3/8'' EUE Box-Pin CASING 5'' WEIGHT 15-18 lbs/FT | D187: unidad | E187: 7726.77 | F187: Material
A188: =A187+1 -> 182 | B188: PCK 50009 | C188: DOUBLE GRIP RETRIEVABLE PACKER MODEL R 7" x 2 7/8'' EUE Box-Pin CASING 7'' WEIGHT 26-29 lbs/FT | D188: unidad | E188: 10599.34 | F188: Material
A189: =A188+1 -> 183 | B189: PCK 50010 | C189: DOUBLE GRIP RETRIEVABLE PACKER MODEL R 7" x 3 1/2'' EUE Box-Pin CASING 7'' WEIGHT 26-29 lbs/FT | D189: unidad | E189: 11570.33 | F189: Material
A190: =A189+1 -> 184 | B190: PCK 50011 | C190: DOUBLE GRIP RETRIEVABLE PACKER MODEL R 9 5/8" x 3 1/2'' EUE Box-Pin CASING 9 5/8'' WEIGHT 47''-53.5 lbs/FT | D190: unidad | E190: 16831.75 | F190: Material
A191: =A190+1 -> 185 | B191: PCK 50012 | C191: MODEL TST-1 MECHANICAL SET PACKER 5" x 2 3/8'' EUE Box-Pin CASING 5'' WEIGHT 18-21 lbs/FT | D191: unidad | E191: 7381.56 | F191: Material
A192: =A191+1 -> 186 | B192: PCK 50013 | C192: MODEL TST-1 MECHANICAL SET PACKER 7" x 2 7/8'' EUE Box-Pin CASING 7'' WEIGHT 26-32 lbs/FT | D192: unidad | E192: 10583.23 | F192: Material
... A354: =A353+1 -> 348 | B354: SFS6292 | C354: TOP PACKER SETTING TOOL ALL SIZE | D354: Corrida | E354: 3975.66 | F354: Servicio
B355: 2.1.30. Servicios de Taponamiento de cemento para desvíos o abandonos de pozo
A356: =A354+1 -> 349 | B356: SC2301 | C356: Viaje unidad de bombeo, para el servicio de cementación forzada | D356: km | E356: 3.15 | F356: Servicio
A357: =A356+1 -> 350 | B357: SC2304 | C357: Primeras 4 horas o fracción, cargo básico por unidad de bombeo alta presión | D357: unidad | E357: 2363.58 | F357: Servicio
A358: =A357+1 -> 351 | B358: SC2305 | C358: Cada hora adicional o fracción de trabajo, por unidad de bombeo alta presión | D358: hr | E358: 125.8 | F358: Servicio
A359: =A358+1 -> 352 | B359: SC2306 | C359: Cargo por profundidad, hasta 11.000 pies. | D359: Pie | E359: 0.07 | F359: Servicio
A360: =A359+1 -> 353 | B360: SC2307 | C360: Cargo por profundidad, de 11.001 hasta 14.000 Pies | D360: Pie | E360: 0.15 | F360: Servicio
A361: =A360+1 -> 354 | B361: SC2308 | C361: Batch mixer de 100 barriles por trabajo | D361: unidad | E361: 689.19 | F361: Servicio
A362: =A361+1 -> 355 | B362: SC2309 | C362: Adaptador de 2 3/8", 2 7/8", 3 1/2", 4 1/2" para cementación forzada | D362: unidad | E362: 44.86 | F362: Servicio
...

Sheet BD
C1: 000 | D1: N/A
C2: 001 | D2: QUITO | E2: BLOQUE UIO | F2: BLOQUE UIO | BN2: B01 | BO2: BLOQUE 01 | BR2: AMILCAR DIAZ ESPINEL | BS2: BLOQUE 58 | BV2: CCDC-028 | BW2: Company Man | BZ2: César Saeteros | CA2: 0602033219 | CD2: Ing. Alejandro Sagal | CE2: 1714829056 | CF2: Coordinador de Producción | CG2: ORION
C3: 002 | D3: INDILLANA | E3: BLOQUE 15 | F3: BLOQUE 15 | BN3: B02 | BO3: BLOQUE 02 | BR3: AGUARICO | BS3: BLOQUE 57 | BV3: CCDC-036 | BW3: Ingeniero de Operaciones | BZ3: José Luis Sáenz | CA3: 1716475585 | CD3: Ing. Alex Fabara | CE3: 1720193281 | CF3: Company man | CG3: SLB
C4: 002 | D4: CONCORDIA | E4: BLOQUE 15 | BN4: B03 | BO4: BLOQUE 03 | BR4: AMISTAD | BS4: BLOQUE 06 | BV4: CCDC-039 | BW4: Supervisor de Producción | BZ4: Carlos Poveda | CA4: 1600165292 | CD4: Ing. Alex Hernández | CE4: 0602958449 | CF4: Ingeniero de Operaciones | CG4: PEC
C5: 002 | D5: ITAYA | E5: BLOQUE 15 | BN5: B05 | BO5: BLOQUE 05 | BR5: ANACONDA | BS5: BLOQUE 61 | BV5: CCDC-040 | BW5: Intendente de Producción | BZ5: Giordano Ferretti | CA5: 1758720617 | CD5: Ing. Alfredo Obando | CE5: 0703887703 | CF5: Company man | CG5: ORION
C6: 002 | D6: JIVINO | E6: BLOQUE 15 | BN6: B06 | BO6: BLOQUE 06 | BR6: ANGEL NORTE | BS6: BLOQUE 15 | BV6: CCDC-042 | BW6: Coordinador de Producción | BZ6: Manolo Salazar | CA6: 1712815180 | CD6: Ing. Andrea Sampedro | CE6: 1718317207 | CF6: Ingeniera de Operaciones | CG6: PEC
C7: 002 | D7: LAGUNA | E7: BLOQUE 15 | BN7: B07 | BO7: BLOQUE 07 | BR7: ANURA | BS7: BLOQUE 61 | BV7: CCDC-051 | BW7: Superintendente de campo | BZ7: Javier Guevara | CA7: 1713206843 | CD7: Ing. Andrés Aldas | CE7: 1712764271 | CF7: Company man | CG7: WAYRA
C8: 002 | D8: NAPO | E8: BLOQUE 15 | BN8: B10 | BO8: BLOQUE 10 | BR8: APAIKA | BS8: BLOQUE 31 | BV8: CCDC-052 | BZ8: Jeferson Lemache | CA8: 0604107870 | CD8: Ing. Andrés Cisneros | CE8: 1717527483 | CF8: Company man | CG8: PEC
C9: 003 | D9: LIMONCOCHA | E9: BLOQUE 15 | BN9: B11 | BO9: BLOQUE 11 | BR9: ARAZA | BS9: BLOQUE 57 | BV9: CCDC-066 | BZ9: July Ana Masache | CA9: 1500239395 | CD9: Ing. Andrés Paredes | CE9: 0401359328 | CF9: Ingeniero de Operaciones | CG9: PEC
C10: 004 | D10: EDEN YUTURI | E10: BLOQUE 12 | F10: BLOQUE 12 | BN10: B12 | BO10: BLOQUE 12 | BR10: ARMADILLO | BS10: BLOQUE 55 | BV10: CCDC-069 | BZ10: Hermes Fabián Páez | CA10: 0502223423 | CD10: Ing. Aníbal Aguilar | CE10: 1719861369 | CF10: Ingeniero de Operaciones | CG10: PEC
C11: 005 | D11: EXPLORACION | F11: BLOQUE EXPLORACION | BN11: B14 | BO11: BLOQUE 14 | BR11: ATACAPI | BS11: BLOQUE 57 | BV11: CSSFD-01 | BZ11: Luis Auquilla | CA11: 0602471153 | CD11: Ing. Anita Guillen | CE11: 0604271320 | CF11: Ingeniera de Operaciones | CG11: PEC
C12: 006 | D12: OLEODUCTO | F12: BLOQUE 12 | BN12: B15 | BO12: BLOQUE 15 | BR12: AUCA | BS12: BLOQUE 61 | BV12: DRILLCOTEC-020 | BZ12: Alberto Tipanluisa | CA12: 1712736485 | CD12: Ing. Arturo Barreiro | CE12: 0914096235 | CF12: Company man | CG12: PEC
C13: 007 | D13: YANAQUINCHA | E13: BLOQUE 15 | F13: BLOQUE 15 | BN13: B16 | BO13: BLOQUE 16 | BR13: AUCA SUR | BS13: BLOQUE 61 | BV13: DT-10 | BZ13: Andrés Pazmiño | CA13: 2100447412 | CD13: Ing. Byron Caiza | CE13: 1722720677 | CF13: Supervisor de Producción | CG13: PEC
C14: 007 | D14: PACAY | E14: BLOQUE 15 | BN14: B17 | BO14: BLOQUE 17 | BR14: BLANCA | BS14: BLOQUE 58 | BV14: DYGOIL-20 | BZ14: Antonio Moreira | CA14: 2100176045 | CD14: Ing. Byron Calero | CE14: 1716336514 | CF14: Company man | CG14: PEC
C15: 007 | D15: ANGEL NORTE | E15: BLOQUE 15 | BN15: B18 | BO15: BLOQUE 18 | BR15: BOA | BS15: BLOQUE 61 | BV15: DYGOIL-30 | BZ15: Sebastian Jimenez | CA15: 1710457837 | CD15: Ing. Carlos Jímenez | CE15: 1002189858 | CF15: Coordinador de Producción | CG15: ORION
C16: 008 | D16: PAKA SUR | E16: BLOQUE 15 | BN16: B20 | BO16: BLOQUE 20 | BR16: CALUMENIA | BS16: BLOQUE 58 | BV16: E&A 12 | BZ16: Carlos Coloma | CA16: 1600153413 | CD16: Ing. Carlos Pineda | CE16: 1710691005 | CF16: Company man | CG16: PNTR
C17: 009 | D17: PAKA NORTE | E17: BLOQUE 15 | BN17: B21 | BO17: BLOQUE 21 | BR17: CEDROS SUR | BS17: BLOQUE 15 | BV17: ELEFANTE AZUL 01 | BZ17: Clinger Yanez | CA17: 1711689370 | CD17: Ing. Carlos Ramírez | CE17: 1804490504 | CF17: Company man | CG17: PEC
C18: 010 | D18: PAÑACOCHA | E18: BLOQUE 12 | F18: BLOQUE 12 | BN18: B22 | BO18: BLOQUE 22 | BR18: CHONTA ESTE | BS18: BLOQUE 61 | BV18: FASTDRILLING-11 | BZ18: Darwin Piña | CA18: 2100549100 | CD18: Ing. Carlos Robalino | CE18: 0502078546 | CF18: Company man | CG18: PEC
C19: 011 | D19: YANKUNT | E19: BLOQUE 15 | F19: BLOQUE 15 | BN19: B28 | BO19: BLOQUE 28 | BR19: COBRA | BS19: BLOQUE 57 | BV19: GEOPETSA-03 | BZ19: Edison Falla | CA19: 1500756067 | CD19: Ing. Carlos Salazar | CE19: 0918279597 | CF19: Supervisor de Producción | CG19: PEC
C20: 011 | D20: PALMAR | E20: BLOQUE 15 | F20: BLOQUE 15 | BN20: B31 | BO20: BLOQUE 31 | BR20: COCA | BS20: BLOQUE 07 | BV20: GEOPETSA-04 | BZ20: Fabián Hernández | CA20: 0603049586 | CD20: Ing. Carlos Toapanta | CE20: 1719353102 | CF20: Company man | CG20: PBELL
C21: 011 | D21: PALMERAS | E21: BLOQUE 15 | F21: BLOQUE 15 | BN21: B43 | BO21: BLOQUE 43 | BR21: CONCORDIA | BS21: BLOQUE 15 | BV21: GEOPETSA-05 | BZ21: Iván Granda | CA21: 1712100138 | CD21: Ing. Carlos Zurita | CE21: 1717192098 | CF21: Ingeniero de Producción | CG21: ANDES
C22: 011 | D22: TUNTIAK | E22: BLOQUE 15 | F22: BLOQUE 15 | BN22: B44 | BO22: BLOQUE 44 | BR22: CONDORAZO | BS22: BLOQUE 57 | BV22: GEOPETSA-06 | BZ22: Omar Bravo | CA22: 1713306601 | CD22: Ing. César Chávez | CE22: 1500568371 | CF22: Company man | CG22: PEC
C23: 011 | D23: TUICH | E23: BLOQUE 15 | F23: BLOQUE 15 | BN23: B45 | BO23: BLOQUE 45 | BR23: CONGA | BS23: BLOQUE 61 | BV23: GEOPETSA-07 | BZ23: Wilber Cárdenas | CA23: 2100116827 | CD23: Ing. César Venegas | CE23: 0927632240 | CF23: Company man | CG23: PEC
C24: 012 | D24: DUMBIQUE | E24: BLOQUE 12 | F24: BLOQUE 12 | BN24: B46 | BO24: BLOQUE 46 | BR24: CONONACO | BS24: BLOQUE 61 | BV24: HILONG 15 | CD24: César Maza | CE24: 1712787991 | CF24: Supervisor de Producción | CG24: PEC
C25: 013 | D25: PAÑAYACU | E25: BLOQUE 15 | F25: BLOQUE 15 | BN25: B47 | BO25: BLOQUE 47 | BR25: CULEBRA | BS25: BLOQUE 61 | BV25: HILONG 28 | CD25: Ing. Cristian Tierra | CE25: 0603607250 | CF25: Supervisor de Producción | CG25: PEC
C26: 040 | D26: OGE SECTORIAL | E26: BLOQUE 40 | F26: BLOQUE 40 | BN26: B48 | BO26: BLOQUE 48 | BR26: CUYABENO | BS26: BLOQUE 58 | BV26: NABORS 794 | CD26: Ing. Cristina Castillo | CE26: 1500536949 | CF26: Ingeniera de Operaciones | CG26: PEC
C27: 015 | D27: CEDROS SUR | E27: BLOQUE 15 | F27: BLOQUE 15 | BN27: B49 | BO27: BLOQUE 49 | BR27: DRAGO | BS27: BLOQUE 57 | BV27: NABORS 814 | CD27: Ing. Daniel Balseca | CE27: 1803906450 | CF27: Company man | CG27: PEC
C28: 015 | D28: QUINDE | E28: BLOQUE 15 | F28: BLOQUE 15 | BN28: B50 | BO28: BLOQUE 50 | BR28: DRAGO NORTE | BS28: BLOQUE 57 | BV28: NABORS 815 | CD28: Ing. Daniel Constante | CE28: 1803789351 | CF28: Ingeniero de Operaciones | CG28: PEC
C29: 016 | D29: DUMBIQUE SUR | E29: BLOQUE 12 | F29: BLOQUE 12 | BN29: B51 | BO29: BLOQUE 51 | BR29: DRAGO ESTE | BS29: BLOQUE 57 | BV29: ORD-902 | CD29: Ing. Daniel Cuenca | CE29: 1714303490 | CF29: Ingeniero de Operaciones | CG29: PEC
C30: 017 | D30: YANAHURCO | E30: BLOQUE 12 | BN30: B52 | BO30: BLOQUE 52 | BR30: DUMBIQUE | BS30: BLOQUE 12 | BV30: ORD-903 | CD30: Ing. Daniel Esparza | CE30: 1712734787 | CF30: Company man | CG30: PEC
C31: 018 | D31: TUMALI ESTE | E31: BLOQUE 12 | BN31: B53 | BO31: BLOQUE 53 | BR31: DUMBIQUE SUR | BS31: BLOQUE 12 | BV31: PETREX-20 | CD31: Ing. Daniel Pabón | CE31: 1002912838 | CF31: Company man | CG31: PEC
C32: 030 | D32: PALO AZUL | E32: BLOQUE 18 | F32: BLOQUE 18 | G32: ZONA OESTE | BN32: B54 | BO32: BLOQUE 54 | BR32: EDEN YUTURI | BS32: BLOQUE 12 | BV32: PETROTECH 04 | CD32: Ing. Daniel Orellana | CE32: 1719240481 | CF32: Supervisor de Producción | CG32: PEC
C33: 031 | D33: PATA | E33: BLOQUE 18 | BN33: B55 | BO33: BLOQUE 55 | BR33: FRONTERA | BS33: BLOQUE 57 | BV33: PW-150 | CD33: Ing. Danny Cuenca | CE33: 1713148003 | CF33: Superintendente de campo | CG33: GOIL
C34: 050 | D34: YURALPA | E34: BLOQUE 21 | F34: BLOQUE 21 | BN34: B56 | BO34: BLOQUE 56 | BR34: GACELA | BS34: BLOQUE 07 | BV34: SAXON 32 | CD34: Ing. Danny Enríquez | CE34: 0400956785 | CF34: Company man | CG34: PEC
C35: 055 | D35: ARMADILLO | E35: BLOQUE 55 | F35: BLOQUE 55 | BN35: B57 | BO35: BLOQUE 57 | BR35: GASODUCTO | BS35: BLOQUE 06 | BV35: SAXON 34 | CD35: Ing. Darwin Mejía | CE35: 1307572782 | CF35: Supervisor de Producción | CG35: PEC
C36: 060 | D36: COCA | E36: BLOQUE 07 | F36: BLOQUE 07 | BN36: B58 | BO36: BLOQUE 58 | BR36: GUANTA | BS36: BLOQUE 56 | BV36: SAXON 47 | CD36: Ing. David Jaque | CE36: 1715419329 | CF36: Ingeniero de Operaciones | CG36: PEC
C37: 061 | D37: PAYAMINO | E37: BLOQUE 07 | BN37: B59 | BO37: BLOQUE 59 | BR37: GUSTAVO GALINDO | BS37: BLOQUE 01 | BV37: SAXON 56 | CD37: Ing. Diana Aviles | CE37: 0927252460 | CF37: Ingeniera de Operaciones | CG37: PEC
C38: 062 | D38: GACELA | E38: BLOQUE 07 | BN38: B60 | BO38: BLOQUE 60 | BR38: HUAICO | BS38: BLOQUE 58 | BV38: SAXON-55 | CD38: Ing. Diego Cunalata | CE38: 1803879210 | CF38: Company man | CG38: PEC
C39: 063 | D39: LOBO | E39: BLOQUE 07 | BN39: B61 | BO39: BLOQUE 61 | BR39: INDILLANA | BS39: BLOQUE 15 | BV39: SAXON-56 | CD39: Ing. Diego Herrera | CE39: 0401095351 | CF39: Ingeniero de Operaciones UIO | CG39: PEC
C40: 064 | D40: MONO | E40: BLOQUE 07 | BN40: B62 | BO40: BLOQUE 62 | BR40: ITAYA | BS40: BLOQUE 15 | BV40: SINOPEC 119 | CD40: Ing. Diego Molina | CE40: 1713267878 | CF40: Company man | CG40: PEC
...

Sheet Clientes
A1: Nombre Fiscal | B1: Identificación
A2: ADRIALPETRO PETROLEUM SERVICES S.A. | B2: 1791406281001
A3: CONDOR SERVICIOS PETROLEROS CONSEPETRO S.A. | B3: 1792832209001
A4: CONSORCIO PETROLERO NACIONAL | B4: 1792723256001
A5: CONSORCIO PETROSUD PETRORIVA | B5: 1791749146001
A6: CONSORCIO PETROLERO PALANDA -YUCA SUR | B6: 1792260787001
A7: CONSORCIO SHUSHUFINDI S.A. | B7: 1792352363001
A8: CPVEN SERVICIOS PETROLEROS LTD | B8: 1791818415001
A9: EMPRESA PUBLICA DE HIDROCARBUROS DEL ECUADOR EP PETROECUADOR | B9: 1768153530001
A10: ENAP SIPETROL S.A. - ENAP SIPEC | B10: 1791239245001
A11: GENTE OIL ECUADOR PTE. LTD. | B11: 1792452929001
A12: GYRODATA ECUADOR L.L.C. | B12: 1792274966001
... A25: XAVIER VASQUEZ | B25: 0603431453

Sheet OTQ
C3: ORDEN DE TRABAJO
C5: RESUMEN DE COSTOS
A7: CONTRATISTA: DYNADRILL ECUADOR C.A. | D7: No. : | E7: 892-OPR-GLCH-022-UIO-2026 | H7: Página 1 de 1
A8: CONTRATO 2025201 - SERVICIOS EVENTUALES BAJO LLAMADA DE APOYO A LAS OPERACIONES, SERVICIOS DE ESTIMULACIÓN Y LIMPIEZA DE POZOS, ACTIVIDADES RELACIONADAS CON LA PRODUCCIÓN, COMPLETACION INICIAL DE POZOS, RENTA DE HERRAMIENTAS DE REACONDICIONAMIENTO/COMPLETACIÓN Y PROVISIÓN DE INSUMOS Y MATERIALES PARA ACTIVIDADES DE CEMENTACIÓN Y TRATAMIENTO DE FLUIDOS ÚNICAMENTE PARA LA PRESTACIÓN DE SERVICIOS RELACIONADOS AL OBJETO DEL CONTRATO EN LOS CAMPOS DE EP PETROECUADOR INCLUIDO BLOQUE 6 (OFFSHORE) | D8: FECHA: | E8: 46233
A9: Descripción del Requerimiento o de la Orden de Trabajo | G9: NOTA: No inicie actividades sin información previa
A10: SERVICIO: | B10: =CONCATENATE([6]TICKET!E17,"/",[6]TICKET!E15,"/",[6]TICKET!E16) -> BOMBEO SISTEMA SOLVENTE ACIDO/GCLH-022/RIGLESS
A11: Las tarifas serán las del Contrato 2025201 las mismas que serán incluidas en la presente hoja de costos estimados
A12: CODIGO | B12: SERVICIOS REQUERIDOS | E12: UNIDAD | F12: TARIFA UNITARIA | G12: CANTIDAD | H12: TOTAL
A13: =+TICKET!D19 -> SFC33001 | B13: =IF(A13="","",IF(ISERROR(VLOOKUP(A13,'[7]LISTA DE PRECIOS'!B$7:E$1788,2,0)),"",VLOOKUP(A13,'[7]LISTA DE PRECIOS'!B$7:E$1788,2,0))) -> Movilización unidad de bombeo para fluidos de completación | E13: =IF(A13="","",IF(ISERROR(VLOOKUP(A13,'[7]LISTA DE PRECIOS'!B$7:E$1788,3,0)),"",VLOOKUP(A13,'[7]LISTA DE PRECIOS'!B$7:E$1788,3,0))) -> km | F13: =IF(A13="","",IF(ISERROR(VLOOKUP(A13,'[7]LISTA DE PRECIOS'!B$7:E$1788,4,0)),"",VLOOKUP(A13,'[7]LISTA DE PRECIOS'!B$7:E$1788,4,0))) -> 3.15 | G13: =+TICKET!E19 -> 33.6 | H13: =+F13*G13 -> 105.84
A14: =+TICKET!D20 -> SB3240 | B14: =IF(A14="","",IF(ISERROR(VLOOKUP(A14,'[7]LISTA DE PRECIOS'!B$7:E$1788,2,0)),"",VLOOKUP(A14,'[7]LISTA DE PRECIOS'!B$7:E$1788,2,0))) -> Cargo básico, primeras 4 horas o fracción de bombeo unidad de estimulación (700 HP) | E14: =IF(A14="","",IF(ISERROR(VLOOKUP(A14,'[7]LISTA DE PRECIOS'!B$7:E$1788,3,0)),"",VLOOKUP(A14,'[7]LISTA DE PRECIOS'!B$7:E$1788,3,0))) -> unidad | F14: =IF(A14="","",IF(ISERROR(VLOOKUP(A14,'[7]LISTA DE PRECIOS'!B$7:E$1788,4,0)),"",VLOOKUP(A14,'[7]LISTA DE PRECIOS'!B$7:E$1788,4,0))) -> 3180.54 | G14: =+TICKET!E20 -> 1 | H14: =+F14*G14 -> 3180.54
A15: =+TICKET!D21 -> SFC33024 | B15: =IF(A15="","",IF(ISERROR(VLOOKUP(A15,'[7]LISTA DE PRECIOS'!B$7:E$1788,2,0)),"",VLOOKUP(A15,'[7]LISTA DE PRECIOS'!B$7:E$1788,2,0))) -> Tanque para ácido o solvente de 6500 galones, por trabajo | E15: =IF(A15="","",IF(ISERROR(VLOOKUP(A15,'[7]LISTA DE PRECIOS'!B$7:E$1788,3,0)),"",VLOOKUP(A15,'[7]LISTA DE PRECIOS'!B$7:E$1788,3,0))) -> unidad | F15: =IF(A15="","",IF(ISERROR(VLOOKUP(A15,'[7]LISTA DE PRECIOS'!B$7:E$1788,4,0)),"",VLOOKUP(A15,'[7]LISTA DE PRECIOS'!B$7:E$1788,4,0))) -> 773.77 | G15: =+TICKET!E21 -> 1 | H15: =+F15*G15 -> 773.77
A16: =+TICKET!D22 -> SFC33032 | B16: =IF(A16="","",IF(ISERROR(VLOOKUP(A16,'[7]LISTA DE PRECIOS'!B$7:E$1788,2,0)),"",VLOOKUP(A16,'[7]LISTA DE PRECIOS'!B$7:E$1788,2,0))) -> Supervisor Senior para fluidos de completación dia o fraccion | E16: =IF(A16="","",IF(ISERROR(VLOOKUP(A16,'[7]LISTA DE PRECIOS'!B$7:E$1788,3,0)),"",VLOOKUP(A16,'[7]LISTA DE PRECIOS'!B$7:E$1788,3,0))) -> día | F16: =IF(A16="","",IF(ISERROR(VLOOKUP(A16,'[7]LISTA DE PRECIOS'!B$7:E$1788,4,0)),"",VLOOKUP(A16,'[7]LISTA DE PRECIOS'!B$7:E$1788,4,0))) -> 833.41 | G16: =+TICKET!E22 -> 1 | H16: =+F16*G16 -> 833.41
A17: =+TICKET!D23 -> SFC33017 | B17: =IF(A17="","",IF(ISERROR(VLOOKUP(A17,'[7]LISTA DE PRECIOS'!B$7:E$1788,2,0)),"",VLOOKUP(A17,'[7]LISTA DE PRECIOS'!B$7:E$1788,2,0))) -> Operador para fluidos de completación dia o fraccion | E17: =IF(A17="","",IF(ISERROR(VLOOKUP(A17,'[7]LISTA DE PRECIOS'!B$7:E$1788,3,0)),"",VLOOKUP(A17,'[7]LISTA DE PRECIOS'!B$7:E$1788,3,0))) -> día | F17: =IF(A17="","",IF(ISERROR(VLOOKUP(A17,'[7]LISTA DE PRECIOS'!B$7:E$1788,4,0)),"",VLOOKUP(A17,'[7]LISTA DE PRECIOS'!B$7:E$1788,4,0))) -> 349.78 | G17: =+TICKET!E23 -> 1 | H17: =+F17*G17 -> 349.78
A18: =+TICKET!D24 -> SFC33017 | B18: =IF(A18="","",IF(ISERROR(VLOOKUP(A18,'[7]LISTA DE PRECIOS'!B$7:E$1788,2,0)),"",VLOOKUP(A18,'[7]LISTA DE PRECIOS'!B$7:E$1788,2,0))) -> Operador para fluidos de completación dia o fraccion | E18: =IF(A18="","",IF(ISERROR(VLOOKUP(A18,'[7]LISTA DE PRECIOS'!B$7:E$1788,3,0)),"",VLOOKUP(A18,'[7]LISTA DE PRECIOS'!B$7:E$1788,3,0))) -> día | F18: =IF(A18="","",IF(ISERROR(VLOOKUP(A18,'[7]LISTA DE PRECIOS'!B$7:E$1788,4,0)),"",VLOOKUP(A18,'[7]LISTA DE PRECIOS'!B$7:E$1788,4,0))) -> 349.78 | G18: =+TICKET!E24 -> 1 | H18: =+F18*G18 -> 349.78
A19: =+TICKET!D25 -> SFC33014 | B19: =IF(A19="","",IF(ISERROR(VLOOKUP(A19,'[7]LISTA DE PRECIOS'!B$7:E$1788,2,0)),"",VLOOKUP(A19,'[7]LISTA DE PRECIOS'!B$7:E$1788,2,0))) -> Tarifa de monitoreo en unidad de bombeo Presión, Densidad, Caudal, Volumen | E19: =IF(A19="","",IF(ISERROR(VLOOKUP(A19,'[7]LISTA DE PRECIOS'!B$7:E$1788,3,0)),"",VLOOKUP(A19,'[7]LISTA DE PRECIOS'!B$7:E$1788,3,0))) -> día | F19: =IF(A19="","",IF(ISERROR(VLOOKUP(A19,'[7]LISTA DE PRECIOS'!B$7:E$1788,4,0)),"",VLOOKUP(A19,'[7]LISTA DE PRECIOS'!B$7:E$1788,4,0))) -> 373.74 | G19: =+TICKET!E25 -> 1 | H19: =+F19*G19 -> 373.74
A20: =+TICKET!D26 -> SFC33011 | B20: =IF(A20="","",IF(ISERROR(VLOOKUP(A20,'[7]LISTA DE PRECIOS'!B$7:E$1788,2,0)),"",VLOOKUP(A20,'[7]LISTA DE PRECIOS'!B$7:E$1788,2,0))) -> Bombeo de fluidos no corrosivos de 2500 hasta 4200 galones | E20: =IF(A20="","",IF(ISERROR(VLOOKUP(A20,'[7]LISTA DE PRECIOS'!B$7:E$1788,3,0)),"",VLOOKUP(A20,'[7]LISTA DE PRECIOS'!B$7:E$1788,3,0))) -> gls | F20: =IF(A20="","",IF(ISERROR(VLOOKUP(A20,'[7]LISTA DE PRECIOS'!B$7:E$1788,4,0)),"",VLOOKUP(A20,'[7]LISTA DE PRECIOS'!B$7:E$1788,4,0))) -> 0.38 | G20: =+TICKET!E26 -> 4200 | H20: =+F20*G20 -> 1596
A21: =+TICKET!D27 -> SFC33007 | B21: =IF(A21="","",IF(ISERROR(VLOOKUP(A21,'[7]LISTA DE PRECIOS'!B$7:E$1788,2,0)),"",VLOOKUP(A21,'[7]LISTA DE PRECIOS'!B$7:E$1788,2,0))) -> Servicio de Bombeo de ácido primeros 2500 galones | E21: =IF(A21="","",IF(ISERROR(VLOOKUP(A21,'[7]LISTA DE PRECIOS'!B$7:E$1788,3,0)),"",VLOOKUP(A21,'[7]LISTA DE PRECIOS'!B$7:E$1788,3,0))) -> gls | F21: =IF(A21="","",IF(ISERROR(VLOOKUP(A21,'[7]LISTA DE PRECIOS'!B$7:E$1788,4,0)),"",VLOOKUP(A21,'[7]LISTA DE PRECIOS'!B$7:E$1788,4,0))) -> 0.34 | G21: =+TICKET!E27 -> 840 | H21: =+F21*G21 -> 285.6
A22: =+TICKET!D28 -> SFC33027 | B22: =IF(A22="","",IF(ISERROR(VLOOKUP(A22,'[7]LISTA DE PRECIOS'!B$7:E$1788,2,0)),"",VLOOKUP(A22,'[7]LISTA DE PRECIOS'!B$7:E$1788,2,0))) -> Movilización de equipo adicional, unidades pesadas. | E22: =IF(A22="","",IF(ISERROR(VLOOKUP(A22,'[7]LISTA DE PRECIOS'!B$7:E$1788,3,0)),"",VLOOKUP(A22,'[7]LISTA DE PRECIOS'!B$7:E$1788,3,0))) -> km | F22: =IF(A22="","",IF(ISERROR(VLOOKUP(A22,'[7]LISTA DE PRECIOS'!B$7:E$1788,4,0)),"",VLOOKUP(A22,'[7]LISTA DE PRECIOS'!B$7:E$1788,4,0))) -> 3.15 | G22: =+TICKET!E28 -> 33.6 | H22: =+F22*G22 -> 105.84
A23: =+TICKET!D29 -> SFC33027 | B23: =IF(A23="","",IF(ISERROR(VLOOKUP(A23,'[7]LISTA DE PRECIOS'!B$7:E$1788,2,0)),"",VLOOKUP(A23,'[7]LISTA DE PRECIOS'!B$7:E$1788,2,0))) -> Movilización de equipo adicional, unidades pesadas. | E23: =IF(A23="","",IF(ISERROR(VLOOKUP(A23,'[7]LISTA DE PRECIOS'!B$7:E$1788,3,0)),"",VLOOKUP(A23,'[7]LISTA DE PRECIOS'!B$7:E$1788,3,0))) -> km | F23: =IF(A23="","",IF(ISERROR(VLOOKUP(A23,'[7]LISTA DE PRECIOS'!B$7:E$1788,4,0)),"",VLOOKUP(A23,'[7]LISTA DE PRECIOS'!B$7:E$1788,4,0))) -> 3.15 | G23: =+TICKET!E29 -> 33.6 | H23: =+F23*G23 -> 105.84
A24: =+TICKET!D30 -> SFC33026 | B24: =IF(A24="","",IF(ISERROR(VLOOKUP(A24,'[7]LISTA DE PRECIOS'!B$7:E$1788,2,0)),"",VLOOKUP(A24,'[7]LISTA DE PRECIOS'!B$7:E$1788,2,0))) -> Movilización unidades livianas para personal | E24: =IF(A24="","",IF(ISERROR(VLOOKUP(A24,'[7]LISTA DE PRECIOS'!B$7:E$1788,3,0)),"",VLOOKUP(A24,'[7]LISTA DE PRECIOS'!B$7:E$1788,3,0))) -> km | F24: =IF(A24="","",IF(ISERROR(VLOOKUP(A24,'[7]LISTA DE PRECIOS'!B$7:E$1788,4,0)),"",VLOOKUP(A24,'[7]LISTA DE PRECIOS'!B$7:E$1788,4,0))) -> 2.66 | G24: =+TICKET!E30 -> 33.6 | H24: =+F24*G24 -> 89.376
... A27: =+TICKET!D33 -> DYFCE-70 | B27: =IF(A27="","",IF(ISERROR(VLOOKUP(A27,'[7]LISTA DE PRECIOS'!B$7:E$1788,2,0)),"",VLOOKUP(A27,'[7]LISTA DE PRECIOS'!B$7:E$1788,2,0))) -> FLUIDO COMPLETACION ESPECIAL TIPO 7 | E27: =IF(A27="","",IF(ISERROR(VLOOKUP(A27,'[7]LISTA DE PRECIOS'!B$7:E$1788,3,0)),"",VLOOKUP(A27,'[7]LISTA DE PRECIOS'!B$7:E$1788,3,0))) -> bbl | F27: =IF(A27="","",IF(ISERROR(VLOOKUP(A27,'[7]LISTA DE PRECIOS'!B$7:E$1788,4,0)),"",VLOOKUP(A27,'[7]LISTA DE PRECIOS'!B$7:E$1788,4,0))) -> 34.9 | G27: =+TICKET!E33 -> 90 | H27: =+F27*G27 -> 3141
B29: =IF(A29="","",IF(ISERROR(VLOOKUP(A29,'[7]LISTA DE PRECIOS'!B$7:E$1788,2,0)),"",VLOOKUP(A29,'[7]LISTA DE PRECIOS'!B$7:E$1788,2,0))) | F29: Valor de la OT: | H29: =SUM(H1:H28) -> 25947.616
B30: Fecha de Inicio: | C30: 46234
B31: Fecha de Terminación: | C31: 46235
A33: REPRESENTANTE DE LA CONTRATISTA (Delegado): | E33: REPRESENTANTE DE EP PETROECUADOR (Delegado):
A34: Nombre: | B34: Ab. Mónica Rojas | E34: Nombre: | F34: =+[6]TICKET!E9 -> Ing. Mónica Quisnancela
A35: Cargo: | B35: Representante Legal | E35: Cargo: | F35: Ingeniero de Operaciones Activo

Sheet TICKET
F1: PREFACTURA | K1: Fecha de Aprobación: 03-07-2026 Revisión: 0
B7: FECHA: | E7: =IF(H12="","",H12) -> 46235 | K7: 4349 | O7: <>
B8: CLIENTE: | E8: EMPRESA PUBLICA DE HIDROCARBUROS DEL ECUADOR EP PETROECUADOR | K8: Condiciones de servicio: Los daños totales o parciales de equipos y/o herramientas, días de espera, equipos y personal, suspensión de trabajo o demás situaciones que pudieran presentarse durante la operación, estarán sujetas a los términos y condiciones del contrato bajo el cual se oferta el presente servicio
B9: SOLICITADO POR: | E9: Ing. Mónica Quisnancela
B10: Verbal | D10: ( ) | E10: Escrita via email | F10: ( x )
B11: NUMERO DE CONTRATO: | E11: 2025201
B12: INICIO TRABAJO: | E12: 46234 | G12: TRABAJO TERMINADO: | H12: 46235
B14: CAMPO / BLOQUE: | E14: GACELA | G14: BLOQUE 07
B15: POZO: | E15: GCLH-022 | G15: GACELA-H022
B16: TALADRO: | E16: RIGLESS
B17: OBSERVACIONES: | E17: BOMBEO SISTEMA SOLVENTE ACIDO
B18: ITEM | D18: CODIGO | E18: CANTIDAD | F18: UNIDAD | G18: DESCRIPCION | K18: PRECIO UNITARIO | L18: PRECIO TOTAL | M18: Tipo | N18: Material | O18: Servicio
B19: 1 | D19: SFC33001 | E19: 33.6 | F19: =IF(D19="","",IF(ISERROR(VLOOKUP(D19,LPPEC,3,0)),"",VLOOKUP(D19,LPPEC,3,0))) -> km | G19: =IF(D19="","",IF(ISERROR(VLOOKUP(D19,LPPEC,2,0)),"",VLOOKUP(D19,LPPEC,2,0))) -> Movilización unidad de bombeo para fluidos de completación | K19: =IF(D19="","",IF(ISERROR(VLOOKUP(D19,LPPEC,4,0)),"",VLOOKUP(D19,LPPEC,4,0))) -> 3.15 | L19: =IF(OR(D19="",E19=""),"",ROUND(E19*K19,2)) -> 105.84 | M19: =IF(D19="","",IF(ISERROR(VLOOKUP(D19,LPPEC,5,0)),"",VLOOKUP(D19,LPPEC,5,0))) -> Servicio | N19: =+IF($M19=N$18,$L19,0) -> 0 | O19: =+IF($M19=O$18,$L19,0) -> 105.84 | P19: CISTERNA
B20: =+B19+1 -> 2 | D20: SB3240 | E20: 1 | F20: =IF(D20="","",IF(ISERROR(VLOOKUP(D20,LPPEC,3,0)),"",VLOOKUP(D20,LPPEC,3,0))) -> unidad | G20: =IF(D20="","",IF(ISERROR(VLOOKUP(D20,LPPEC,2,0)),"",VLOOKUP(D20,LPPEC,2,0))) -> Cargo básico, primeras 4 horas o fracción de bombeo unidad de estimulación (700 HP) | K20: =IF(D20="","",IF(ISERROR(VLOOKUP(D20,LPPEC,4,0)),"",VLOOKUP(D20,LPPEC,4,0))) -> 3180.54 | L20: =IF(OR(D20="",E20=""),"",ROUND(E20*K20,2)) -> 3180.54 | M20: =IF(D20="","",IF(ISERROR(VLOOKUP(D20,LPPEC,5,0)),"",VLOOKUP(D20,LPPEC,5,0))) -> Servicio | N20: =+IF($M20=N$18,$L20,0) -> 0 | O20: =+IF($M20=O$18,$L20,0) -> 3180.54
B21: =+B20+1 -> 3 | D21: SFC33024 | E21: 1 | F21: =IF(D21="","",IF(ISERROR(VLOOKUP(D21,LPPEC,3,0)),"",VLOOKUP(D21,LPPEC,3,0))) -> unidad | G21: =IF(D21="","",IF(ISERROR(VLOOKUP(D21,LPPEC,2,0)),"",VLOOKUP(D21,LPPEC,2,0))) -> Tanque para ácido o solvente de 6500 galones, por trabajo | K21: =IF(D21="","",IF(ISERROR(VLOOKUP(D21,LPPEC,4,0)),"",VLOOKUP(D21,LPPEC,4,0))) -> 773.77 | L21: =IF(OR(D21="",E21=""),"",ROUND(E21*K21,2)) -> 773.77 | M21: =IF(D21="","",IF(ISERROR(VLOOKUP(D21,LPPEC,5,0)),"",VLOOKUP(D21,LPPEC,5,0))) -> Servicio | N21: =+IF($M21=N$18,$L21,0) -> 0 | O21: =+IF($M21=O$18,$L21,0) -> 773.77
B22: =+B21+1 -> 4 | D22: SFC33032 | E22: 1 | F22: =IF(D22="","",IF(ISERROR(VLOOKUP(D22,LPPEC,3,0)),"",VLOOKUP(D22,LPPEC,3,0))) -> día | G22: =IF(D22="","",IF(ISERROR(VLOOKUP(D22,LPPEC,2,0)),"",VLOOKUP(D22,LPPEC,2,0))) -> Supervisor Senior para fluidos de completación dia o fraccion | K22: =IF(D22="","",IF(ISERROR(VLOOKUP(D22,LPPEC,4,0)),"",VLOOKUP(D22,LPPEC,4,0))) -> 833.41 | L22: =IF(OR(D22="",E22=""),"",ROUND(E22*K22,2)) -> 833.41 | M22: =IF(D22="","",IF(ISERROR(VLOOKUP(D22,LPPEC,5,0)),"",VLOOKUP(D22,LPPEC,5,0))) -> Servicio | N22: =+IF($M22=N$18,$L22,0) -> 0 | O22: =+IF($M22=O$18,$L22,0) -> 833.41 | P22: JAVIER GUEVARA
B23: =+B22+1 -> 5 | D23: SFC33017 | E23: 1 | F23: =IF(D23="","",IF(ISERROR(VLOOKUP(D23,LPPEC,3,0)),"",VLOOKUP(D23,LPPEC,3,0))) -> día | G23: =IF(D23="","",IF(ISERROR(VLOOKUP(D23,LPPEC,2,0)),"",VLOOKUP(D23,LPPEC,2,0))) -> Operador para fluidos de completación dia o fraccion | K23: =IF(D23="","",IF(ISERROR(VLOOKUP(D23,LPPEC,4,0)),"",VLOOKUP(D23,LPPEC,4,0))) -> 349.78 | L23: =IF(OR(D23="",E23=""),"",ROUND(E23*K23,2)) -> 349.78 | M23: =IF(D23="","",IF(ISERROR(VLOOKUP(D23,LPPEC,5,0)),"",VLOOKUP(D23,LPPEC,5,0))) -> Servicio | N23: =+IF($M23=N$18,$L23,0) -> 0 | O23: =+IF($M23=O$18,$L23,0) -> 349.78 | P23: JEFERSON LEMACHE
B24: =+B23+1 -> 6 | D24: SFC33017 | E24: 1 | F24: =IF(D24="","",IF(ISERROR(VLOOKUP(D24,LPPEC,3,0)),"",VLOOKUP(D24,LPPEC,3,0))) -> día | G24: =IF(D24="","",IF(ISERROR(VLOOKUP(D24,LPPEC,2,0)),"",VLOOKUP(D24,LPPEC,2,0))) -> Operador para fluidos de completación dia o fraccion | K24: =IF(D24="","",IF(ISERROR(VLOOKUP(D24,LPPEC,4,0)),"",VLOOKUP(D24,LPPEC,4,0))) -> 349.78 | L24: =IF(OR(D24="",E24=""),"",ROUND(E24*K24,2)) -> 349.78 | M24: =IF(D24="","",IF(ISERROR(VLOOKUP(D24,LPPEC,5,0)),"",VLOOKUP(D24,LPPEC,5,0))) -> Servicio | N24: =+IF($M24=N$18,$L24,0) -> 0 | O24: =+IF($M24=O$18,$L24,0) -> 349.78 | P24: CRISTIAN REINO
B25: =+B24+1 -> 7 | D25: SFC33014 | E25: 1 | F25: =IF(D25="","",IF(ISERROR(VLOOKUP(D25,LPPEC,3,0)),"",VLOOKUP(D25,LPPEC,3,0))) -> día | G25: =IF(D25="","",IF(ISERROR(VLOOKUP(D25,LPPEC,2,0)),"",VLOOKUP(D25,LPPEC,2,0))) -> Tarifa de monitoreo en unidad de bombeo Presión, Densidad, Caudal, Volumen | K25: =IF(D25="","",IF(ISERROR(VLOOKUP(D25,LPPEC,4,0)),"",VLOOKUP(D25,LPPEC,4,0))) -> 373.74 | L25: =IF(OR(D25="",E25=""),"",ROUND(E25*K25,2)) -> 373.74 | M25: =IF(D25="","",IF(ISERROR(VLOOKUP(D25,LPPEC,5,0)),"",VLOOKUP(D25,LPPEC,5,0))) -> Servicio | N25: =+IF($M25=N$18,$L25,0) -> 0 | O25: =+IF($M25=O$18,$L25,0) -> 373.74
B26: =+B25+1 -> 8 | D26: SFC33011 | E26: 4200 | F26: =IF(D26="","",IF(ISERROR(VLOOKUP(D26,LPPEC,3,0)),"",VLOOKUP(D26,LPPEC,3,0))) -> gls | G26: =IF(D26="","",IF(ISERROR(VLOOKUP(D26,LPPEC,2,0)),"",VLOOKUP(D26,LPPEC,2,0))) -> Bombeo de fluidos no corrosivos de 2500 hasta 4200 galones | K26: =IF(D26="","",IF(ISERROR(VLOOKUP(D26,LPPEC,4,0)),"",VLOOKUP(D26,LPPEC,4,0))) -> 0.38 | L26: =IF(OR(D26="",E26=""),"",ROUND(E26*K26,2)) -> 1596 | M26: =IF(D26="","",IF(ISERROR(VLOOKUP(D26,LPPEC,5,0)),"",VLOOKUP(D26,LPPEC,5,0))) -> Servicio | N26: =+IF($M26=N$18,$L26,0) -> 0 | O26: =+IF($M26=O$18,$L26,0) -> 1596
B27: =+B26+1 -> 9 | D27: SFC33007 | E27: 840 | F27: =IF(D27="","",IF(ISERROR(VLOOKUP(D27,LPPEC,3,0)),"",VLOOKUP(D27,LPPEC,3,0))) -> gls | G27: =IF(D27="","",IF(ISERROR(VLOOKUP(D27,LPPEC,2,0)),"",VLOOKUP(D27,LPPEC,2,0))) -> Servicio de Bombeo de ácido primeros 2500 galones | K27: =IF(D27="","",IF(ISERROR(VLOOKUP(D27,LPPEC,4,0)),"",VLOOKUP(D27,LPPEC,4,0))) -> 0.34 | L27: =IF(OR(D27="",E27=""),"",ROUND(E27*K27,2)) -> 285.6 | M27: =IF(D27="","",IF(ISERROR(VLOOKUP(D27,LPPEC,5,0)),"",VLOOKUP(D27,LPPEC,5,0))) -> Servicio | N27: =+IF($M27=N$18,$L27,0) -> 0 | O27: =+IF($M27=O$18,$L27,0) -> 285.6
B28: =+B27+1 -> 10 | D28: SFC33027 | E28: 33.6 | F28: =IF(D28="","",IF(ISERROR(VLOOKUP(D28,LPPEC,3,0)),"",VLOOKUP(D28,LPPEC,3,0))) -> km | G28: =IF(D28="","",IF(ISERROR(VLOOKUP(D28,LPPEC,2,0)),"",VLOOKUP(D28,LPPEC,2,0))) -> Movilización de equipo adicional, unidades pesadas. | K28: =IF(D28="","",IF(ISERROR(VLOOKUP(D28,LPPEC,4,0)),"",VLOOKUP(D28,LPPEC,4,0))) -> 3.15 | L28: =IF(OR(D28="",E28=""),"",ROUND(E28*K28,2)) -> 105.84 | M28: =IF(D28="","",IF(ISERROR(VLOOKUP(D28,LPPEC,5,0)),"",VLOOKUP(D28,LPPEC,5,0))) -> Servicio | N28: =+IF($M28=N$18,$L28,0) -> 0 | O28: =+IF($M28=O$18,$L28,0) -> 105.84
B29: =+B28+1 -> 11 | D29: SFC33027 | E29: 33.6 | F29: =IF(D29="","",IF(ISERROR(VLOOKUP(D29,LPPEC,3,0)),"",VLOOKUP(D29,LPPEC,3,0))) -> km | G29: =IF(D29="","",IF(ISERROR(VLOOKUP(D29,LPPEC,2,0)),"",VLOOKUP(D29,LPPEC,2,0))) -> Movilización de equipo adicional, unidades pesadas. | K29: =IF(D29="","",IF(ISERROR(VLOOKUP(D29,LPPEC,4,0)),"",VLOOKUP(D29,LPPEC,4,0))) -> 3.15 | L29: =IF(OR(D29="",E29=""),"",ROUND(E29*K29,2)) -> 105.84 | M29: =IF(D29="","",IF(ISERROR(VLOOKUP(D29,LPPEC,5,0)),"",VLOOKUP(D29,LPPEC,5,0))) -> Servicio | N29: =+IF($M29=N$18,$L29,0) -> 0 | O29: =+IF($M29=O$18,$L29,0) -> 105.84 | P29: CAMION CON QUIMICA
B30: =+B29+1 -> 12 | D30: SFC33026 | E30: 33.6 | F30: =IF(D30="","",IF(ISERROR(VLOOKUP(D30,LPPEC,3,0)),"",VLOOKUP(D30,LPPEC,3,0))) -> km | G30: =IF(D30="","",IF(ISERROR(VLOOKUP(D30,LPPEC,2,0)),"",VLOOKUP(D30,LPPEC,2,0))) -> Movilización unidades livianas para personal | K30: =IF(D30="","",IF(ISERROR(VLOOKUP(D30,LPPEC,4,0)),"",VLOOKUP(D30,LPPEC,4,0))) -> 2.66 | L30: =IF(OR(D30="",E30=""),"",ROUND(E30*K30,2)) -> 89.38 | M30: =IF(D30="","",IF(ISERROR(VLOOKUP(D30,LPPEC,5,0)),"",VLOOKUP(D30,LPPEC,5,0))) -> Servicio | N30: =+IF($M30=N$18,$L30,0) -> 0 | O30: =+IF($M30=O$18,$L30,0) -> 89.38
B31: =+B30+1 -> 13 | D31: DYTERP-150 | E31: 110 | F31: =IF(D31="","",IF(ISERROR(VLOOKUP(D31,LPPEC,3,0)),"",VLOOKUP(D31,LPPEC,3,0))) -> gls | G31: =IF(D31="","",IF(ISERROR(VLOOKUP(D31,LPPEC,2,0)),"",VLOOKUP(D31,LPPEC,2,0))) -> Solvente Base Terpenos biodegradable | K31: =IF(D31="","",IF(ISERROR(VLOOKUP(D31,LPPEC,4,0)),"",VLOOKUP(D31,LPPEC,4,0))) -> 35.73 | L31: =IF(OR(D31="",E31=""),"",ROUND(E31*K31,2)) -> 3930.3 | M31: =IF(D31="","",IF(ISERROR(VLOOKUP(D31,LPPEC,5,0)),"",VLOOKUP(D31,LPPEC,5,0))) -> Material | N31: =+IF($M31=N$18,$L31,0) -> 3930.3 | O31: =+IF($M31=O$18,$L31,0) -> 0
B32: =+B31+1 -> 14 | D32: DYMBA-100 | E32: 840 | F32: =IF(D32="","",IF(ISERROR(VLOOKUP(D32,LPPEC,3,0)),"",VLOOKUP(D32,LPPEC,3,0))) -> gls | G32: =IF(D32="","",IF(ISERROR(VLOOKUP(D32,LPPEC,2,0)),"",VLOOKUP(D32,LPPEC,2,0))) -> SISTEMA REMOVEDOR DE CARBONATOS ORGÁNICO | K32: =IF(D32="","",IF(ISERROR(VLOOKUP(D32,LPPEC,4,0)),"",VLOOKUP(D32,LPPEC,4,0))) -> 12.77 | L32: =IF(OR(D32="",E32=""),"",ROUND(E32*K32,2)) -> 10726.8 | M32: =IF(D32="","",IF(ISERROR(VLOOKUP(D32,LPPEC,5,0)),"",VLOOKUP(D32,LPPEC,5,0))) -> Material | N32: =+IF($M32=N$18,$L32,0) -> 10726.8 | O32: =+IF($M32=O$18,$L32,0) -> 0
B33: =+B32+1 -> 15 | D33: DYFCE-70 | E33: 90 | F33: =IF(D33="","",IF(ISERROR(VLOOKUP(D33,LPPEC,3,0)),"",VLOOKUP(D33,LPPEC,3,0))) -> bbl | G33: =IF(D33="","",IF(ISERROR(VLOOKUP(D33,LPPEC,2,0)),"",VLOOKUP(D33,LPPEC,2,0))) -> FLUIDO COMPLETACION ESPECIAL TIPO 7 | K33: =IF(D33="","",IF(ISERROR(VLOOKUP(D33,LPPEC,4,0)),"",VLOOKUP(D33,LPPEC,4,0))) -> 34.9 | L33: =IF(OR(D33="",E33=""),"",ROUND(E33*K33,2)) -> 3141 | M33: =IF(D33="","",IF(ISERROR(VLOOKUP(D33,LPPEC,5,0)),"",VLOOKUP(D33,LPPEC,5,0))) -> Material | N33: =+IF($M33=N$18,$L33,0) -> 3141 | O33: =+IF($M33=O$18,$L33,0) -> 0
B34: Los precios no incluyen IVA | G34: Subtotal materiales: | H34: =+N34 -> 17798.1 | I34: Subtotal Servicios: | J34: =+O34 -> 8149.52 | K34: SUBTOTAL | L34: =SUM(L19:L33) -> 25947.62 | N34: =SUM(N19:N33) -> 17798.1 | O34: =SUM(O19:O33) -> 8149.52
K36: TOTAL | L36: =L34-L35 -> 25947.62
B37: Firma electrónica autorizada por Dynadrill Ecuador C.A.: ILDA ZAMBRANO | N37: 285626.27
D43: Representante Dynadrill Ecuador C.A.: | J43: Aprobado Cliente | K43: Ingeniero de Operaciones | N43: =IF(K44="","",IF(ISERROR(VLOOKUP(K44,BD!CD$2:CG$118,3,0)),"",VLOOKUP(K44,BD!CD$2:CG$118,3,0))) -> Ingeniero de Operaciones | O43: =+IF(K43=N43,"OK","Revisar") -> OK
D44: Nombre: | E44: Javier Guevara | J44: Nombre : | K44: Ing. Jorge Cruz
D45: C.I.: | E45: =IF(E44="","",IF(ISERROR(VLOOKUP(E44,BD!BZ$2:CA$23,2,0)),"",VLOOKUP(E44,BD!BZ$2:CA$23,2,0))) -> 1713206843 | J45: C.I.: | N45: =IF(K44="","",IF(ISERROR(VLOOKUP(K44,BD!CD$2:CG$118,2,0)),"",VLOOKUP(K44,BD!CD$2:CG$118,2,0))) -> 1205792391 | O45: =+IF(K45=N45,"OK","Revisar") -> Revisar

Sheet Reporte Job 
E1: REPORTE DIARIO DE ACTIVIDADES DE OPERACIONES | I1: Fecha de Aprobación: 03-07-2026
I2: Revisión: 0
B4: Fecha: | E4: =+TICKET!H12 -> 46235 | I4: Nº | J4: =IF([5]TICKET!K7="","",[5]TICKET!K7) -> 4349
B5: Cliente: | E5: =+[5]TICKET!E8 -> EMPRESA PUBLICA DE HIDROCARBUROS DEL ECUADOR EP PETROECUADOR | H5: Orden/Contrato Nº: | J5: =+TICKET!E11 -> 2025201
B6: Pozo: | E6: =+TICKET!E15 -> GCLH-022 | I6: Representante del Cliente: | J6: =+TICKET!K44 -> Ing. Jorge Cruz
B7: Campo/Bloque: | E7: =IF([5]TICKET!E14="","",[5]TICKET!E14&" / "&[5]TICKET!G14) -> GACELA / BLOQUE 07 | I7: Cargo: | J7: =IF([5]TICKET!K43="","",[5]TICKET!K43) -> Ingeniero de Operaciones
B8: Taladro: | E8: =IF([5]TICKET!E16="","",[5]TICKET!E16) -> RIGLESS
B9: DURACIÓN | E9: DETALLE DE ACTIVIDADES | N9: Horas OPE
B10: Inicio | C10: Fin | D10: Horas | N10: PUMP
B11: 46234
B12: 0.625 | C12: 0.66666667 | D12: =IF(OR(B12="",C12=""),0,IF(AND(B12<>"",C12<>"",B12<C12),(C12-B12)*24,IF(AND(B12<>"",C12<>"",B12>C12),((C12-B12)*24)+24,IF(B12-C12=0,24,"Error")))) -> 1 | E12: Personal y equipos de Cia Dynadrill arriban al pozo GCLH-022. Coordina trabajo con Ingeniero de Operaciones. Gestiona permiso de trabajo y realiza reunión de seguridad con todo personal involucrado. Cia Dynadrill ubica las siguientes unidades: 1 Unidad de bombeo (700 HP) 1 Tanque 6500 galones 1 Camión Plataforma con accesorios de bomba y quimica 1 Camioneta para movimiento del personal
B13: 0.66666667 | C13: 0.75 | D13: =IF(OR(B13="",C13=""),0,IF(AND(B13<>"",C13<>"",B13<C13),(C13-B13)*24,IF(AND(B13<>"",C13<>"",B13>C13),((C13-B13)*24)+24,IF(B13-C13=0,24,"Error")))) -> 2 | E13: Personal de Cia Dynadrill realiza rig up de equipos, arma linea de 4" desde tanque de 6500 galones hacia Unidad de Bombeo, desde Unidad de Bombeo arma linea de alta presion de 2" Fig 1502 hacia cabezal del pozo. Se instala monitoreo en Unidad de Bombeo de Presion, Densidad, Caudal y Volumen. Realiza prueba de presion con 2000 psi por 5 min. OK. En simultaneo se recibe 310 galones de Jp1 en tanque de 6500 galones de Cia Dynadrill. | N13: 0.5
B14: 0.75 | C14: 0.79166667 | D14: =IF(OR(B14="",C14=""),0,IF(AND(B14<>"",C14<>"",B14<C14),(C14-B14)*24,IF(AND(B14<>"",C14<>"",B14>C14),((C14-B14)*24)+24,IF(B14-C14=0,24,"Error")))) -> 1 | E14: Con autorizacion del cliente, se prepara tratamiento solvente-acido de acuerdo a la siguiente tabla:
F15: FASE SOLVENTE | I15: 10
F16: JP1 | G16: =IF(F16="","",IF(ISERROR(VLOOKUP(F16,[8]LP!B$6:E$1799,2,0)),"",VLOOKUP(F16,[8]LP!B$6:E$1799,2,0))) | I16: 310
F17: DYTERP-150 | G17: =IF(F17="","",IF(ISERROR(VLOOKUP(F17,[8]LP!B$6:E$1799,2,0)),"",VLOOKUP(F17,[8]LP!B$6:E$1799,2,0))) -> Solvente Base Terpenos biodegradable | I17: 110
F19: FASE ACIDO ORGANICO | I19: 20
F20: DYMBA-100 | G20: =IF(F20="","",IF(ISERROR(VLOOKUP(F20,[8]LP!B$6:E$1799,2,0)),"",VLOOKUP(F20,[8]LP!B$6:E$1799,2,0))) -> SISTEMA REMOVEDOR DE CARBONATOS ORGÁNICO | I20: =I19*42 -> 840
F22: FLUIDO DE CONTROL ESPECIAL | I22: 90
F23: DYFCE-70 | G23: =IF(F23="","",IF(ISERROR(VLOOKUP(F23,[8]LP!B$6:E$1799,2,0)),"",VLOOKUP(F23,[8]LP!B$6:E$1799,2,0))) -> FLUIDO COMPLETACION ESPECIAL TIPO 7 | I23: =I22 -> 90
E24: Nota: Se utiliza tanque de 6500 galones de Cia Dynadrill.
B25: 0.79166667 | C25: 0.91666667 | D25: =IF(OR(B25="",C25=""),0,IF(AND(B25<>"",C25<>"",B25<C25),(C25-B25)*24,IF(AND(B25<>"",C25<>"",B25>C25),((C25-B25)*24)+24,IF(B25-C25=0,24,"Error")))) -> 3 | E25: Con Unidad de Bombeo de Cia Dynadrill se bombea 10 bbl de sistema solvente y 20 bbl de sistema acido organico hacia profundidad de camisa (10149 ft) a 1,0 bpm y 150 psi de presion de circulacion. Se desplaza con 70 bls de fluido de completacion especial tipo 7 a 1,0 bpm con 150 psi inicial y termina desplazamiento con 350 psi. Posteriormente cierra anulares y forza sistema acido organico desplazandolos con 20 bbl de fluido de completación especial tipo 7 a 0,9 bpm y 350 psi de presion de circulacion. Se deja tratamiento y se espera 6 horas. Nota: La operación se registró en unidad de monitoreo de presión, densidad, caudal y volumen de Cia Dynadrill (1 día ítem SFC33014) | N25: 3
B27: 0.91666667 | C27: 0.95833333 | D27: =IF(OR(B27="",C27=""),0,IF(AND(B27<>"",C27<>"",B27<C27),(C27-B27)*24,IF(AND(B27<>"",C27<>"",B27>C27),((C27-B27)*24)+24,IF(B27-C27=0,24,"Error")))) -> 1 | E27: Tratamiento químico en reposo en el pozo. Personal de Cia Dynadrill realiza rig down de unidades, orden y limpieza en locacion.
B28: 0.95833333 | C28: 0.25 | D28: =IF(OR(B28="",C28=""),0,IF(AND(B28<>"",C28<>"",B28<C28),(C28-B28)*24,IF(AND(B28<>"",C28<>"",B28>C28),((C28-B28)*24)+24,IF(B28-C28=0,24,"Error")))) -> 7 | E28: Personal y equipos de Cia Dynadrill en espera de dispoción del cliente.
B29: 46235
B30: 0.25 | C30: 0.58333333 | D30: =IF(OR(B30="",C30=""),0,IF(AND(B30<>"",C30<>"",B30<C30),(C30-B30)*24,IF(AND(B30<>"",C30<>"",B30>C30),((C30-B30)*24)+24,IF(B30-C30=0,24,"Error")))) -> 8 | E30: Corrida # 01 se acopla pilling tool de 2,5" bajan a recuperar bomba jet de 2,81. Corrida # 02 se cambia pines y nuevamente se acopla pilling tool de 2,5 y bajan a intentar recuperar bomba jet de 2,81. Corrida # 03 se cambia pines y nuevamente se acopla pilling tool de 2,5" y bajan a intentar recuperar bomba jet de 2,81. Personal y equipos de Cía Dynadrill con autorización del cleinte se retira a Base coca.
E31: Por
E32: Bombeo de Fluidos corrosivos aplicable al Ítem SFC33007: | M32: =M31-4 -> -4
E33: SISTEMA ACIDO | H33: 20
E34: TOTAL FLUIDOS CORROSIVOS BOMBEADO SFC33007: | H34: =SUM(H33:H33) -> 20 | I34: =+H34*42 -> 840
E35: Bombeo de Fluidos no corrosivo aplicable al Ítem SFC33011:
E36: SISTEMA SOLVENTE | H36: 10
E37: FLUIDO DE CONTROL | H37: 70
E38: DESPLAZAMIENTO | H38: 20
E39: TOTAL FLUIDOS NO CORROSIVOS BOMBEADO Ítem SFC33011: | H39: =SUM(H36:H38) -> 100 | I39: =+H39*42 -> 4200
B41: Tiempo productivo: | E41: =SUM(D11:D39) -> 23 | G41: Tiempo No productivo: | H41: 0 | I41: Tiempo Total: | K41: =+E41+H41 -> 23 | N41: =SUM(N11:N40) -> 3.5
B42: Observaciones:
E43: =IF(N41=0,"La Unidad de Bombeo no registra aun horas de trabajo",IF(N41>4,"El tiempo de operación de la Unidad de Bombeo son "&N41&" horas"&" equivalentes a 1 cargo básico y "&N51&" horas","El tiempo de operación aplicable de la Unidad de Bombeo es un cargo básico por las primeras 4 horas o fracción de operación")) -> El tiempo de operación aplicable de la Unidad de Bombeo es un cargo básico por las primeras 4 horas o fracción de operación
E44: El tiempo aplicable al personal en la operación de Bombeo Solvente Acido es de dos días (31/07/2026) (01/08/2026)
E45: Equipos: Unidad de Bombeo, Tanque de 6500 galones
...

Sheet GUIA
B12: CLIENTE: | D12: EMPRESA PUBLICA DE HIDROCARBUROS DEL ECUADOR EP PETROECUADOR | F12: RUC: 1768153530001 | H12: HORA SALIDA:
B13: SOLICITADO POR: | D13: =TICKET!E9 -> Ing. Mónica Quisnancela
B14: DESPACHADO POR: | D14: Carlos Calderon | H14: HORA LLEGADA:
B15: LUGAR DE ORIGEN: Coca Base Dynadrill | F15: DATOS DE LA PERSONA ENCARGADA DEL TRANSPORTE
B16: CAMPO: | D16: GACELA | F16: NOMBRE O RAZÓN SOCIAL: | G16: Javier Guevara
B17: POZO: | D17: =+TICKET!E15 -> GCLH-022 | F17: RUC / CEDULA: 1713206843 | G17: FIRMA: …………………………..
B18: FECHA: | D18: 46234 | F18: VEHICULO: Camion Chevrolet NQR | G18: PLACAS: | H18: PDR-7543 | M18: X
B19: ITEM | C19: CANTIDAD | D19: SERIAL/CODIGO | E19: UNIDAD DE MEDIDA | F19: DESCRIPCION | M19: Validador
B20: =+IF(D20="","",1) -> 1 | C20: =+TICKET!E31 -> 110 | D20: =TICKET!D31 -> DYTERP-150 | E20: =IF(D20="","",IF(ISERROR(VLOOKUP(D20,[3]LP!B$6:E$1799,3,0)),"",VLOOKUP(D20,[3]LP!B$6:E$1799,3,0))) -> gls | F20: =IF(D20="","",IF(ISERROR(VLOOKUP(D20,[3]LP!B$6:E$1799,2,0)),"",VLOOKUP(D20,[3]LP!B$6:E$1799,2,0))) -> Solvente Base Terpenos biodegradable | M20: =IF(D20="","",IF(ISERROR(VLOOKUP(D20,LPPEC,5,0)),"",VLOOKUP(D20,LPPEC,5,0))) -> Material
B21: =+IF(D21="","",1) -> 1 | C21: =+TICKET!E32 -> 840 | D21: =TICKET!D32 -> DYMBA-100 | E21: =IF(D21="","",IF(ISERROR(VLOOKUP(D21,[3]LP!B$6:E$1799,3,0)),"",VLOOKUP(D21,[3]LP!B$6:E$1799,3,0))) -> gls | F21: =IF(D21="","",IF(ISERROR(VLOOKUP(D21,[3]LP!B$6:E$1799,2,0)),"",VLOOKUP(D21,[3]LP!B$6:E$1799,2,0))) -> SISTEMA REMOVEDOR DE CARBONATOS ORGÁNICO | M21: =IF(D21="","",IF(ISERROR(VLOOKUP(D21,LPPEC,5,0)),"",VLOOKUP(D21,LPPEC,5,0))) -> Material
B22: =+IF(D22="","",1) -> 1 | C22: =+TICKET!E33 -> 90 | D22: =TICKET!D33 -> DYFCE-70 | E22: =IF(D22="","",IF(ISERROR(VLOOKUP(D22,[3]LP!B$6:E$1799,3,0)),"",VLOOKUP(D22,[3]LP!B$6:E$1799,3,0))) -> bbl | F22: =IF(D22="","",IF(ISERROR(VLOOKUP(D22,[3]LP!B$6:E$1799,2,0)),"",VLOOKUP(D22,[3]LP!B$6:E$1799,2,0))) -> FLUIDO COMPLETACION ESPECIAL TIPO 7 | M22: =IF(D22="","",IF(ISERROR(VLOOKUP(D22,LPPEC,5,0)),"",VLOOKUP(D22,LPPEC,5,0))) -> Material
M23: =IF(D23="","",IF(ISERROR(VLOOKUP(D23,LPPEC,5,0)),"",VLOOKUP(D23,LPPEC,5,0)))
M24: =IF(D24="","",IF(ISERROR(VLOOKUP(D24,LPPEC,5,0)),"",VLOOKUP(D24,LPPEC,5,0)))
B25: =IF(AND(B$20=1,D25<>""),#REF!+1,"") | E25: =IF(D25="","",IF(ISERROR(VLOOKUP(D25,[3]LP!B$6:E$1799,3,0)),"",VLOOKUP(D25,[3]LP!B$6:E$1799,3,0))) | F25: =IF(D25="","",IF(ISERROR(VLOOKUP(D25,[3]LP!B$6:E$1799,2,0)),"",VLOOKUP(D25,[3]LP!B$6:E$1799,2,0))) | M25: =IF(D25="","",IF(ISERROR(VLOOKUP(D25,LPPEC,5,0)),"",VLOOKUP(D25,LPPEC,5,0)))
C29: x
C30: Entregue Conforme | G30: Recibi Conforme
C31: =+[3]TICKET!E86 -> Carlos Poveda | F31: Nombre: | G31: =+TICKET!K44 -> Ing. Jorge Cruz
F32: Cargo: | G32: =+[3]TICKET!K85 -> Ingeniero de Operaciones
F33: CI: | G33: =+[3]TICKET!K87 -> #REF!

Sheet BD Pozos
G4: DOCUMENTO: | H4: REGISTRO DE POZOS EN OPEN WELLS
G5: FUENTE: | H5: EDM - OPEN WELLS & REGISTRO OFICIAL DE PAM NOMENCLATURAS DE POZOS
G6: ELABORADO: | H6: GERENCIMIENTO DE DATOS
A7: BLOQUE | B7: ACTIVO | C7: CAMPO | D7: PAD | E7: NOMBRE LARGO POZO | F7: NOMBRE CORTO POZO | G7: WELLBORE | H7: BLOQUE ID | I7: BLOQUE | J7: ACTIVO | K7: CAMPO | L7: PAD | M7: NOMBRE LARGO POZO | N7: Tipo
A8: B01 | B8: LA | C8: PACOA | D8: PAD | E8: PACOA-023 | F8: PAC-023 | G8: PAC-023 | H8: =+A8 -> B01 | I8: =IF(ISERROR(VLOOKUP(H8,BD!BN$2:BO$51,2,FALSE)),"",VLOOKUP(H8,BD!BN$2:BO$51,2,FALSE)) -> BLOQUE 01 | J8: =IF(B8="","",B8) -> LA | K8: =+C8 -> PACOA | L8: =+D8 -> PAD | M8: =+IF(F8=F7,E8&RIGHT(G8,2),E8) -> PACOA-023 | N8: Open Wells
A9: B01 | B9: LA | C9: PACOA | D9: PAD | E9: SAN PABLO-001 | F9: SNP-001 | G9: SNP-001 | H9: =+A9 -> B01 | I9: =IF(ISERROR(VLOOKUP(H9,BD!BN$2:BO$51,2,FALSE)),"",VLOOKUP(H9,BD!BN$2:BO$51,2,FALSE)) -> BLOQUE 01 | J9: =IF(B9="","",B9) -> LA | K9: =+C9 -> PACOA | L9: =+D9 -> PAD | M9: =+IF(F9=F8,E9&RIGHT(G9,2),E9) -> SAN PABLO-001 | N9: Open Wells
A10: B01 | B10: LA | C10: PACOA | D10: PAD | E10: PACOA-002 | F10: PAC-002 | G10: PAC-002 | H10: =+A10 -> B01 | I10: =IF(ISERROR(VLOOKUP(H10,BD!BN$2:BO$51,2,FALSE)),"",VLOOKUP(H10,BD!BN$2:BO$51,2,FALSE)) -> BLOQUE 01 | J10: =IF(B10="","",B10) -> LA | K10: =+C10 -> PACOA | L10: =+D10 -> PAD | M10: =+IF(F10=F9,E10&RIGHT(G10,2),E10) -> PACOA-002 | N10: Open Wells
A11: B01 | B11: LA | C11: PACOA | D11: PAD | E11: PACOA-004 | F11: PAC-004 | G11: PAC-004 | H11: =+A11 -> B01 | I11: =IF(ISERROR(VLOOKUP(H11,BD!BN$2:BO$51,2,FALSE)),"",VLOOKUP(H11,BD!BN$2:BO$51,2,FALSE)) -> BLOQUE 01 | J11: =IF(B11="","",B11) -> LA | K11: =+C11 -> PACOA | L11: =+D11 -> PAD | M11: =+IF(F11=F10,E11&RIGHT(G11,2),E11) -> PACOA-004 | N11: Open Wells
A12: B01 | B12: LA | C12: PACOA | D12: PAD | E12: PACOA-005 | F12: PAC-005 | G12: PAC-005 | H12: =+A12 -> B01 | I12: =IF(ISERROR(VLOOKUP(H12,BD!BN$2:BO$51,2,FALSE)),"",VLOOKUP(H12,BD!BN$2:BO$51,2,FALSE)) -> BLOQUE 01 | J12: =IF(B12="","",B12) -> LA | K12: =+C12 -> PACOA | L12: =+D12 -> PAD | M12: =+IF(F12=F11,E12&RIGHT(G12,2),E12) -> PACOA-005 | N12: Open Wells
A13: B01 | B13: LA | C13: PACOA | D13: PAD | E13: PACOA-008 | F13: PAC-008 | G13: PAC-008 | H13: =+A13 -> B01 | I13: =IF(ISERROR(VLOOKUP(H13,BD!BN$2:BO$51,2,FALSE)),"",VLOOKUP(H13,BD!BN$2:BO$51,2,FALSE)) -> BLOQUE 01 | J13: =IF(B13="","",B13) -> LA | K13: =+C13 -> PACOA | L13: =+D13 -> PAD | M13: =+IF(F13=F12,E13&RIGHT(G13,2),E13) -> PACOA-008 | N13: Open Wells
A14: B01 | B14: LA | C14: PACOA | D14: PAD | E14: PACOA-007 | F14: PAC-007 | G14: PAC-007 | H14: =+A14 -> B01 | I14: =IF(ISERROR(VLOOKUP(H14,BD!BN$2:BO$51,2,FALSE)),"",VLOOKUP(H14,BD!BN$2:BO$51,2,FALSE)) -> BLOQUE 01 | J14: =IF(B14="","",B14) -> LA | K14: =+C14 -> PACOA | L14: =+D14 -> PAD | M14: =+IF(F14=F13,E14&RIGHT(G14,2),E14) -> PACOA-007 | N14: Open Wells
A15: B01 | B15: LA | C15: PACOA | D15: PAD | E15: PACOA-016 | F15: PAC-016 | G15: PAC-016 | H15: =+A15 -> B01 | I15: =IF(ISERROR(VLOOKUP(H15,BD!BN$2:BO$51,2,FALSE)),"",VLOOKUP(H15,BD!BN$2:BO$51,2,FALSE)) -> BLOQUE 01 | J15: =IF(B15="","",B15) -> LA | K15: =+C15 -> PACOA | L15: =+D15 -> PAD | M15: =+IF(F15=F14,E15&RIGHT(G15,2),E15) -> PACOA-016 | N15: Open Wells
A16: B01 | B16: LA | C16: PACOA | D16: PAD | E16: PACOA-017 | F16: PAC-017 | G16: PAC-017 | H16: =+A16 -> B01 | I16: =IF(ISERROR(VLOOKUP(H16,BD!BN$2:BO$51,2,FALSE)),"",VLOOKUP(H16,BD!BN$2:BO$51,2,FALSE)) -> BLOQUE 01 | J16: =IF(B16="","",B16) -> LA | K16: =+C16 -> PACOA | L16: =+D16 -> PAD | M16: =+IF(F16=F15,E16&RIGHT(G16,2),E16) -> PACOA-017 | N16: Open Wells
A17: B01 | B17: LA | C17: PACOA | D17: PAD | E17: PACOA-024 | F17: PAC-024 | G17: PAC-024 | H17: =+A17 -> B01 | I17: =IF(ISERROR(VLOOKUP(H17,BD!BN$2:BO$51,2,FALSE)),"",VLOOKUP(H17,BD!BN$2:BO$51,2,FALSE)) -> BLOQUE 01 | J17: =IF(B17="","",B17) -> LA | K17: =+C17 -> PACOA | L17: =+D17 -> PAD | M17: =+IF(F17=F16,E17&RIGHT(G17,2),E17) -> PACOA-024 | N17: Open Wells
A18: B01 | B18: LA | C18: PACOA | D18: PAD | E18: PACOA-036 | F18: PAC-036 | G18: PAC-036 | H18: =+A18 -> B01 | I18: =IF(ISERROR(VLOOKUP(H18,BD!BN$2:BO$51,2,FALSE)),"",VLOOKUP(H18,BD!BN$2:BO$51,2,FALSE)) -> BLOQUE 01 | J18: =IF(B18="","",B18) -> LA | K18: =+C18 -> PACOA | L18: =+D18 -> PAD | M18: =+IF(F18=F17,E18&RIGHT(G18,2),E18) -> PACOA-036 | N18: Open Wells
A19: B01 | B19: LA | C19: PACOA | D19: PAD | E19: PACOA-033 | F19: PAC-033 | G19: PAC-033 | H19: =+A19 -> B01 | I19: =IF(ISERROR(VLOOKUP(H19,BD!BN$2:BO$51,2,FALSE)),"",VLOOKUP(H19,BD!BN$2:BO$51,2,FALSE)) -> BLOQUE 01 | J19: =IF(B19="","",B19) -> LA | K19: =+C19 -> PACOA | L19: =+D19 -> PAD | M19: =+IF(F19=F18,E19&RIGHT(G19,2),E19) -> PACOA-033 | N19: Open Wells
... A293: B07 | B293: OY | C293: OSO | D293: PAD G | E293: OSO-G063H | F293: OSOG-063H | G293: OSOG-063H | H293: =+A293 -> B07 | I293: =IF(ISERROR(VLOOKUP(H293,BD!BN$2:BO$51,2,FALSE)),"",VLOOKUP(H293,BD!BN$2:BO$51,2,FALSE)) -> BLOQUE 07 | J293: =IF(B293="","",B293) -> OY | K293: =+C293 -> OSO | L293: =+D293 -> PAD G | M293: =+IF(F293=F292,E293&RIGHT(G293,2),E293) -> OSO-G063H | N293: Open Wells
A294: B07 | B294: OY | C294: OSO | D294: PAD G | E294: OSO-G063H | F294: OSOG-063H | G294: OSOG-063HR1 | H294: =+A294 -> B07 | I294: =IF(ISERROR(VLOOKUP(H294,BD!BN$2:BO$51,2,FALSE)),"",VLOOKUP(H294,BD!BN$2:BO$51,2,FALSE)) -> BLOQUE 07 | J294: =IF(B294="","",B294) -> OY | K294: =+C294 -> OSO | L294: =+D294 -> PAD G | M294: =+IF(F294=F293,E294&RIGHT(G294,2),E294) -> OSO-G063HR1 | N294: Updated Open wells | P294: Difiere de Open Wells, prima el registro oficial
A295: B07 | B295: OY | C295: OSO | D295: PAD G | E295: OSO-G063H | F295: OSOG-063H | G295: OSOG-063HS1 | H295: =+A295 -> B07 | I295: =IF(ISERROR(VLOOKUP(H295,BD!BN$2:BO$51,2,FALSE)),"",VLOOKUP(H295,BD!BN$2:BO$51,2,FALSE)) -> BLOQUE 07 | J295: =IF(B295="","",B295) -> OY | K295: =+C295 -> OSO | L295: =+D295 -> PAD G | M295: =+IF(F295=F294,E295&RIGHT(G295,2),E295) -> OSO-G063HS1 | N295: Updated Open wells | P295: Difiere de Open Wells, prima el registro oficial
A296: B07 | B296: OY | C296: OSO | D296: PAD G | E296: OSO-G063H | F296: OSOG-063H | G296: OSOG-063HS2 | H296: =+A296 -> B07 | I296: =IF(ISERROR(VLOOKUP(H296,BD!BN$2:BO$51,2,FALSE)),"",VLOOKUP(H296,BD!BN$2:BO$51,2,FALSE)) -> BLOQUE 07 | J296: =IF(B296="","",B296) -> OY | K296: =+C296 -> OSO | L296: =+D296 -> PAD G | M296: =+IF(F296=F295,E296&RIGHT(G296,2),E296) -> OSO-G063HS2 | N296: Registro oficial PAM
A297: B07 | B297: OY | C297: OSO | D297: PAD G | E297: OSO-G081 | F297: OSOG-081 | G297: OSOG-081 | H297: =+A297 -> B07 | I297: =IF(ISERROR(VLOOKUP(H297,BD!BN$2:BO$51,2,FALSE)),"",VLOOKUP(H297,BD!BN$2:BO$51,2,FALSE)) -> BLOQUE 07 | J297: =IF(B297="","",B297) -> OY | K297: =+C297 -> OSO | L297: =+D297 -> PAD G | M297: =+IF(F297=F296,E297&RIGHT(G297,2),E297) -> OSO-G081 | N297: Open Wells
A298: B07 | B298: OY | C298: OSO | D298: PAD G | E298: OSO-G097 | F298: OSOG-097 | G298: OSOG-097 | H298: =+A298 -> B07 | I298: =IF(ISERROR(VLOOKUP(H298,BD!BN$2:BO$51,2,FALSE)),"",VLOOKUP(H298,BD!BN$2:BO$51,2,FALSE)) -> BLOQUE 07 | J298: =IF(B298="","",B298) -> OY | K298: =+C298 -> OSO | L298: =+D298 -> PAD G | M298: =+IF(F298=F297,E298&RIGHT(G298,2),E298) -> OSO-G097 | N298: Open Wells
A299: B07 | B299: OY | C299: OSO | D299: PAD G | E299: OSO-G067 | F299: OSOG-067 | G299: OSOG-067 | H299: =+A299 -> B07 | I299: =IF(ISERROR(VLOOKUP(H299,BD!BN$2:BO$51,2,FALSE)),"",VLOOKUP(H299,BD!BN$2:BO$51,2,FALSE)) -> BLOQUE 07 | J299: =IF(B299="","",B299) -> OY | K299: =+C299 -> OSO | L299: =+D299 -> PAD G | M299: =+IF(F299=F298,E299&RIGHT(G299,2),E299) -> OSO-G067 | N299: Open Wells
A300: B07 | B300: OY | C300: OSO | D300: PAD G | E300: OSO-G067 | F300: OSOG-067 | G300: OSOG-067R1 | H300: =+A300 -> B07 | I300: =IF(ISERROR(VLOOKUP(H300,BD!BN$2:BO$51,2,FALSE)),"",VLOOKUP(H300,BD!BN$2:BO$51,2,FALSE)) -> BLOQUE 07 | J300: =IF(B300="","",B300) -> OY | K300: =+C300 -> OSO | L300: =+D300 -> PAD G | M300: =+IF(F300=F299,E300&RIGHT(G300,2),E300) -> OSO-G067R1 | N300: Open Wells
A301: B07 | B301: OY | C301: OSO | D301: PAD G | E301: OSO-G086H | F301: OSOG-086H | G301: OSOG-086H | H301: =+A301 -> B07 | I301: =IF(ISERROR(VLOOKUP(H301,BD!BN$2:BO$51,2,FALSE)),"",VLOOKUP(H301,BD!BN$2:BO$51,2,FALSE)) -> BLOQUE 07 | J301: =IF(B301="","",B301) -> OY | K301: =+C301 -> OSO | L301: =+D301 -> PAD G | M301: =+IF(F301=F300,E301&RIGHT(G301,2),E301) -> OSO-G086H | N301: Open Wells
A302: B07 | B302: OY | C302: OSO | D302: PAD G | E302: OSO-G086H | F302: OSOG-086H | G302: OSOG-086S1 | H302: =+A302 -> B07 | I302: =IF(ISERROR(VLOOKUP(H302,BD!BN$2:BO$51,2,FALSE)),"",VLOOKUP(H302,BD!BN$2:BO$51,2,FALSE)) -> BLOQUE 07 | J302: =IF(B302="","",B302) -> OY | K302: =+C302 -> OSO | L302: =+D302 -> PAD G | M302: =+IF(F302=F301,E302&RIGHT(G302,2),E302) -> OSO-G086HS1 | N302: Open Wells
A303: B07 | B303: OY | C303: OSO | D303: PAD G | E303: OSO-G086H | F303: OSOG-086H | G303: OSOG-086S2 | H303: =+A303 -> B07 | I303: =IF(ISERROR(VLOOKUP(H303,BD!BN$2:BO$51,2,FALSE)),"",VLOOKUP(H303,BD!BN$2:BO$51,2,FALSE)) -> BLOQUE 07 | J303: =IF(B303="","",B303) -> OY | K303: =+C303 -> OSO | L303: =+D303 -> PAD G | M303: =+IF(F303=F302,E303&RIGHT(G303,2),E303) -> OSO-G086HS2 | N303: Open Wells
A304: B07 | B304: OY | C304: OSO | D304: PAD G | E304: OSO-G089H | F304: OSOG-089H | G304: OSOG-089H | H304: =+A304 -> B07 | I304: =IF(ISERROR(VLOOKUP(H304,BD!BN$2:BO$51,2,FALSE)),"",VLOOKUP(H304,BD!BN$2:BO$51,2,FALSE)) -> BLOQUE 07 | J304: =IF(B304="","",B304) -> OY | K304: =+C304 -> OSO | L304: =+D304 -> PAD G | M304: =+IF(F304=F303,E304&RIGHT(G304,2),E304) -> OSO-G089H | N304: Open Wells
A305: B07 | B305: OY | C305: OSO | D305: PAD G | E305: OSO-G069 | F305: OSOG-069 | G305: OSOG-069 | H305: =+A305 -> B07 | I305: =IF(ISERROR(VLOOKUP(H305,BD!BN$2:BO$51,2,FALSE)),"",VLOOKUP(H305,BD!BN$2:BO$51,2,FALSE)) -> BLOQUE 07 | J305: =IF(B305="","",B305) -> OY | K305: =+C305 -> OSO | L305: =+D305 -> PAD G | M305: =+IF(F305=F304,E305&RIGHT(G305,2),E305) -> OSO-G069 | N305: Open Wells
A306: B07 | B306: OY | C306: OSO | D306: PAD G | E306: OSO-G061 | F306: OSOG-061 | G306: OSOG-061 | H306: =+A306 -> B07 | I306: =IF(ISERROR(VLOOKUP(H306,BD!BN$2:BO$51,2,FALSE)),"",VLOOKUP(H306,BD!BN$2:BO$51,2,FALSE)) -> BLOQUE 07 | J306: =IF(B306="","",B306) -> OY | K306: =+C306 -> OSO | L306: =+D306 -> PAD G | M306: =+IF(F306=F305,E306&RIGHT(G306,2),E306) -> OSO-G061 | N306: Open Wells
A307: B07 | B307: OY | C307: OSO | D307: PAD G | E307: OSO-G065 | F307: OSOG-065 | G307: OSOG-065 | H307: =+A307 -> B07 | I307: =IF(ISERROR(VLOOKUP(H307,BD!BN$2:BO$51,2,FALSE)),"",VLOOKUP(H307,BD!BN$2:BO$51,2,FALSE)) -> BLOQUE 07 | J307: =IF(B307="","",B307) -> OY | K307: =+C307 -> OSO | L307: =+D307 -> PAD G | M307: =+IF(F307=F306,E307&RIGHT(G307,2),E307) -> OSO-G065 | N307: Open Wells
... A392: B07 | B392: OY | C392: PUNINO | D392: PAD A | E392: PUNINO-A001 | F392: PNNA-001 | G392: PNNA-001 | H392: =+A392 -> B07 | I392: =IF(ISERROR(VLOOKUP(H392,BD!BN$2:BO$51,2,FALSE)),"",VLOOKUP(H392,BD!BN$2:BO$51,2,FALSE)) -> BLOQUE 07 | J392: =IF(B392="","",B392) -> OY | K392: =+C392 -> PUNINO | L392: =+D392 -> PAD A | M392: =+IF(F392=F391,E392&RIGHT(G392,2),E392) -> PUNINO-A001 | N392: Open Wells
A393: B10 | C393: OGLAN ANGLO | D393: PAD | E393: OGLAN ANGLO-001 | F393: OGA-001 | G393: OGA-001 | H393: =+A393 -> B10 | I393: =IF(ISERROR(VLOOKUP(H393,BD!BN$2:BO$51,2,FALSE)),"",VLOOKUP(H393,BD!BN$2:BO$51,2,FALSE)) -> BLOQUE 10 | J393: =IF(B393="","",B393) | K393: =+C393 -> OGLAN ANGLO | L393: =+D393 -> PAD | M393: =+IF(F393=F392,E393&RIGHT(G393,2),E393) -> OGLAN ANGLO-001 | N393: Open Wells
A394: B11 | C394: CAMINO | D394: PAD | E394: CAMINO-001 | F394: CMN-001 | G394: CMN-001 | H394: =+A394 -> B11 | I394: =IF(ISERROR(VLOOKUP(H394,BD!BN$2:BO$51,2,FALSE)),"",VLOOKUP(H394,BD!BN$2:BO$51,2,FALSE)) -> BLOQUE 11 | J394: =IF(B394="","",B394) | K394: =+C394 -> CAMINO | L394: =+D394 -> PAD | M394: =+IF(F394=F393,E394&RIGHT(G394,2),E394) -> CAMINO-001 | N394: Open Wells
A395: B11 | C395: OCHENTA | D395: PAD | E395: OCHENTA-001 | F395: OCH-001 | G395: OCH-001 | H395: =+A395 -> B11 | I395: =IF(ISERROR(VLOOKUP(H395,BD!BN$2:BO$51,2,FALSE)),"",VLOOKUP(H395,BD!BN$2:BO$51,2,FALSE)) -> BLOQUE 11 | J395: =IF(B395="","",B395) | K395: =+C395 -> OCHENTA | L395: =+D395 -> PAD | M395: =+IF(F395=F394,E395&RIGHT(G395,2),E395) -> OCHENTA-001 | N395: Open Wells
A396: B11 | C396: PUSINO | D396: PAD | E396: PUSINO-001 | F396: PSN-001 | G396: PSN-001 | H396: =+A396 -> B11 | I396: =IF(ISERROR(VLOOKUP(H396,BD!BN$2:BO$51,2,FALSE)),"",VLOOKUP(H396,BD!BN$2:BO$51,2,FALSE)) -> BLOQUE 11 | J396: =IF(B396="","",B396) | K396: =+C396 -> PUSINO | L396: =+D396 -> PAD | M396: =+IF(F396=F395,E396&RIGHT(G396,2),E396) -> PUSINO-001 | N396: Open Wells
